2023-06-29 15:55:20|27648|INFO|ytopt:46] 

Loading ytopt
--------------
2023-06-29 15:55:20|27648|ERROR|ytopt:49] Uncaught exception:
Traceback (most recent call last):
  File "/Users/praveen_paramasivam/anaconda3/envs/ytuneV1/lib/python3.10/runpy.py", line 196, in _run_module_as_main
    return _run_code(code, main_globals, None,
  File "/Users/praveen_paramasivam/anaconda3/envs/ytuneV1/lib/python3.10/runpy.py", line 86, in _run_code
    exec(code, run_globals)
  File "/Users/praveen_paramasivam/workspace/anl/ytoptWorkspaceNew/ytuneV1/ytopt/ytopt/search/ambs.py", line 125, in <module>
    search = AMBS(**vars(args))
  File "/Users/praveen_paramasivam/workspace/anl/ytoptWorkspaceNew/ytuneV1/ytopt/ytopt/search/ambs.py", line 45, in __init__
    super().__init__(**kwargs)
  File "/Users/praveen_paramasivam/workspace/anl/ytoptWorkspaceNew/ytuneV1/ytopt/ytopt/search/search.py", line 38, in __init__
    self.problem = util.generic_loader(problem, 'Problem')
  File "/Users/praveen_paramasivam/workspace/anl/ytoptWorkspaceNew/ytuneV1/ytopt/ytopt/search/util.py", line 125, in generic_loader
    return load_attr_from(target)
  File "/Users/praveen_paramasivam/workspace/anl/ytoptWorkspaceNew/ytuneV1/ytopt/ytopt/search/util.py", line 100, in load_attr_from
    module = import_module(str_module)
  File "/Users/praveen_paramasivam/anaconda3/envs/ytuneV1/lib/python3.10/importlib/__init__.py", line 126, in import_module
    return _bootstrap._gcd_import(name[level:], package, level)
  File "<frozen importlib._bootstrap>", line 1050, in _gcd_import
  File "<frozen importlib._bootstrap>", line 1027, in _find_and_load
  File "<frozen importlib._bootstrap>", line 1006, in _find_and_load_unlocked
  File "<frozen importlib._bootstrap>", line 688, in _load_unlocked
  File "<frozen importlib._bootstrap_external>", line 883, in exec_module
  File "<frozen importlib._bootstrap>", line 241, in _call_with_frames_removed
  File "/Users/praveen_paramasivam/workspace/anl/ytoptWorkspaceNew/ytuneV1/ytopt-libensemble/ytopt-libe-deeplearning/pytorch/ytopt/problem.py", line 3, in <module>
    from autotune import TuningProblem
ImportError: cannot import name 'TuningProblem' from 'autotune' (/Users/praveen_paramasivam/workspace/anl/ytoptWorkspaceNew/ytuneV1/autotune/autotune/__init__.py)
2023-06-29 16:00:33|28303|INFO|ytopt:46] 

Loading ytopt
--------------
2023-06-29 16:00:33|28303|ERROR|ytopt:49] Uncaught exception:
Traceback (most recent call last):
  File "/Users/praveen_paramasivam/anaconda3/envs/ytuneV1/lib/python3.10/runpy.py", line 196, in _run_module_as_main
    return _run_code(code, main_globals, None,
  File "/Users/praveen_paramasivam/anaconda3/envs/ytuneV1/lib/python3.10/runpy.py", line 86, in _run_code
    exec(code, run_globals)
  File "/Users/praveen_paramasivam/workspace/anl/ytoptWorkspaceNew/ytuneV1/ytopt/ytopt/search/ambs.py", line 125, in <module>
    search = AMBS(**vars(args))
  File "/Users/praveen_paramasivam/workspace/anl/ytoptWorkspaceNew/ytuneV1/ytopt/ytopt/search/ambs.py", line 45, in __init__
    super().__init__(**kwargs)
  File "/Users/praveen_paramasivam/workspace/anl/ytoptWorkspaceNew/ytuneV1/ytopt/ytopt/search/search.py", line 38, in __init__
    self.problem = util.generic_loader(problem, 'Problem')
  File "/Users/praveen_paramasivam/workspace/anl/ytoptWorkspaceNew/ytuneV1/ytopt/ytopt/search/util.py", line 125, in generic_loader
    return load_attr_from(target)
  File "/Users/praveen_paramasivam/workspace/anl/ytoptWorkspaceNew/ytuneV1/ytopt/ytopt/search/util.py", line 100, in load_attr_from
    module = import_module(str_module)
  File "/Users/praveen_paramasivam/anaconda3/envs/ytuneV1/lib/python3.10/importlib/__init__.py", line 126, in import_module
    return _bootstrap._gcd_import(name[level:], package, level)
  File "<frozen importlib._bootstrap>", line 1050, in _gcd_import
  File "<frozen importlib._bootstrap>", line 1027, in _find_and_load
  File "<frozen importlib._bootstrap>", line 1006, in _find_and_load_unlocked
  File "<frozen importlib._bootstrap>", line 688, in _load_unlocked
  File "<frozen importlib._bootstrap_external>", line 883, in exec_module
  File "<frozen importlib._bootstrap>", line 241, in _call_with_frames_removed
  File "/Users/praveen_paramasivam/workspace/anl/ytoptWorkspaceNew/ytuneV1/ytopt-libensemble/ytopt-libe-deeplearning/pytorch/ytopt/problem.py", line 3, in <module>
    from autotune import TuningProblem
ImportError: cannot import name 'TuningProblem' from 'autotune' (/Users/praveen_paramasivam/workspace/anl/ytoptWorkspaceNew/ytuneV1/autotune/autotune/__init__.py)
2023-06-29 16:02:52|28753|INFO|ytopt:46] 

Loading ytopt
--------------
2023-06-29 16:02:52|28753|ERROR|ytopt:49] Uncaught exception:
Traceback (most recent call last):
  File "/Users/praveen_paramasivam/anaconda3/envs/ytuneV1/lib/python3.10/runpy.py", line 196, in _run_module_as_main
    return _run_code(code, main_globals, None,
  File "/Users/praveen_paramasivam/anaconda3/envs/ytuneV1/lib/python3.10/runpy.py", line 86, in _run_code
    exec(code, run_globals)
  File "/Users/praveen_paramasivam/workspace/anl/ytoptWorkspaceNew/ytuneV1/ytopt/ytopt/search/ambs.py", line 125, in <module>
    search = AMBS(**vars(args))
  File "/Users/praveen_paramasivam/workspace/anl/ytoptWorkspaceNew/ytuneV1/ytopt/ytopt/search/ambs.py", line 45, in __init__
    super().__init__(**kwargs)
  File "/Users/praveen_paramasivam/workspace/anl/ytoptWorkspaceNew/ytuneV1/ytopt/ytopt/search/search.py", line 38, in __init__
    self.problem = util.generic_loader(problem, 'Problem')
  File "/Users/praveen_paramasivam/workspace/anl/ytoptWorkspaceNew/ytuneV1/ytopt/ytopt/search/util.py", line 125, in generic_loader
    return load_attr_from(target)
  File "/Users/praveen_paramasivam/workspace/anl/ytoptWorkspaceNew/ytuneV1/ytopt/ytopt/search/util.py", line 100, in load_attr_from
    module = import_module(str_module)
  File "/Users/praveen_paramasivam/anaconda3/envs/ytuneV1/lib/python3.10/importlib/__init__.py", line 126, in import_module
    return _bootstrap._gcd_import(name[level:], package, level)
  File "<frozen importlib._bootstrap>", line 1050, in _gcd_import
  File "<frozen importlib._bootstrap>", line 1027, in _find_and_load
  File "<frozen importlib._bootstrap>", line 1006, in _find_and_load_unlocked
  File "<frozen importlib._bootstrap>", line 688, in _load_unlocked
  File "<frozen importlib._bootstrap_external>", line 883, in exec_module
  File "<frozen importlib._bootstrap>", line 241, in _call_with_frames_removed
  File "/Users/praveen_paramasivam/workspace/anl/ytoptWorkspaceNew/ytuneV1/ytopt-libensemble/ytopt-libe-deeplearning/pytorch/ytopt/problem.py", line 3, in <module>
    from autotune import TuningProblem
ImportError: cannot import name 'TuningProblem' from 'autotune' (/Users/praveen_paramasivam/workspace/anl/ytoptWorkspaceNew/ytuneV1/autotune/autotune/__init__.py)
2023-06-29 16:06:57|29294|INFO|ytopt:46] 

Loading ytopt
--------------
2023-06-29 16:06:57|29294|ERROR|ytopt:49] Uncaught exception:
Traceback (most recent call last):
  File "/Users/praveen_paramasivam/anaconda3/envs/ytuneV1/lib/python3.10/runpy.py", line 196, in _run_module_as_main
    return _run_code(code, main_globals, None,
  File "/Users/praveen_paramasivam/anaconda3/envs/ytuneV1/lib/python3.10/runpy.py", line 86, in _run_code
    exec(code, run_globals)
  File "/Users/praveen_paramasivam/workspace/anl/ytoptWorkspaceNew/ytuneV1/ytopt/ytopt/search/ambs.py", line 125, in <module>
    search = AMBS(**vars(args))
  File "/Users/praveen_paramasivam/workspace/anl/ytoptWorkspaceNew/ytuneV1/ytopt/ytopt/search/ambs.py", line 45, in __init__
    super().__init__(**kwargs)
  File "/Users/praveen_paramasivam/workspace/anl/ytoptWorkspaceNew/ytuneV1/ytopt/ytopt/search/search.py", line 38, in __init__
    self.problem = util.generic_loader(problem, 'Problem')
  File "/Users/praveen_paramasivam/workspace/anl/ytoptWorkspaceNew/ytuneV1/ytopt/ytopt/search/util.py", line 125, in generic_loader
    return load_attr_from(target)
  File "/Users/praveen_paramasivam/workspace/anl/ytoptWorkspaceNew/ytuneV1/ytopt/ytopt/search/util.py", line 100, in load_attr_from
    module = import_module(str_module)
  File "/Users/praveen_paramasivam/anaconda3/envs/ytuneV1/lib/python3.10/importlib/__init__.py", line 126, in import_module
    return _bootstrap._gcd_import(name[level:], package, level)
  File "<frozen importlib._bootstrap>", line 1050, in _gcd_import
  File "<frozen importlib._bootstrap>", line 1027, in _find_and_load
  File "<frozen importlib._bootstrap>", line 1006, in _find_and_load_unlocked
  File "<frozen importlib._bootstrap>", line 688, in _load_unlocked
  File "<frozen importlib._bootstrap_external>", line 883, in exec_module
  File "<frozen importlib._bootstrap>", line 241, in _call_with_frames_removed
  File "/Users/praveen_paramasivam/workspace/anl/ytoptWorkspaceNew/ytuneV1/ytopt-libensemble/ytopt-libe-deeplearning/pytorch/ytopt/problem.py", line 3, in <module>
    from autotune import TuningProblem
ImportError: cannot import name 'TuningProblem' from 'autotune' (/Users/praveen_paramasivam/workspace/anl/ytoptWorkspaceNew/ytuneV1/autotune/autotune/__init__.py)
2023-06-29 16:09:39|29599|INFO|ytopt:46] 

Loading ytopt
--------------
2023-06-29 16:09:39|29599|ERROR|ytopt:49] Uncaught exception:
Traceback (most recent call last):
  File "/Users/praveen_paramasivam/anaconda3/envs/ytuneV1/lib/python3.10/runpy.py", line 196, in _run_module_as_main
    return _run_code(code, main_globals, None,
  File "/Users/praveen_paramasivam/anaconda3/envs/ytuneV1/lib/python3.10/runpy.py", line 86, in _run_code
    exec(code, run_globals)
  File "/Users/praveen_paramasivam/workspace/anl/ytoptWorkspaceNew/ytuneV1/ytopt/ytopt/search/ambs.py", line 125, in <module>
    search = AMBS(**vars(args))
  File "/Users/praveen_paramasivam/workspace/anl/ytoptWorkspaceNew/ytuneV1/ytopt/ytopt/search/ambs.py", line 45, in __init__
    super().__init__(**kwargs)
  File "/Users/praveen_paramasivam/workspace/anl/ytoptWorkspaceNew/ytuneV1/ytopt/ytopt/search/search.py", line 38, in __init__
    self.problem = util.generic_loader(problem, 'Problem')
  File "/Users/praveen_paramasivam/workspace/anl/ytoptWorkspaceNew/ytuneV1/ytopt/ytopt/search/util.py", line 125, in generic_loader
    return load_attr_from(target)
  File "/Users/praveen_paramasivam/workspace/anl/ytoptWorkspaceNew/ytuneV1/ytopt/ytopt/search/util.py", line 100, in load_attr_from
    module = import_module(str_module)
  File "/Users/praveen_paramasivam/anaconda3/envs/ytuneV1/lib/python3.10/importlib/__init__.py", line 126, in import_module
    return _bootstrap._gcd_import(name[level:], package, level)
  File "<frozen importlib._bootstrap>", line 1050, in _gcd_import
  File "<frozen importlib._bootstrap>", line 1027, in _find_and_load
  File "<frozen importlib._bootstrap>", line 1006, in _find_and_load_unlocked
  File "<frozen importlib._bootstrap>", line 688, in _load_unlocked
  File "<frozen importlib._bootstrap_external>", line 883, in exec_module
  File "<frozen importlib._bootstrap>", line 241, in _call_with_frames_removed
  File "/Users/praveen_paramasivam/workspace/anl/ytoptWorkspaceNew/ytuneV1/ytopt-libensemble/ytopt-libe-deeplearning/pytorch/ytopt/problem.py", line 63, in <module>
    Problem = TuningProblem(
TypeError: TuningProblem.__init__() missing 1 required positional argument: 'parameter_space'
2023-06-29 16:09:53|29625|INFO|ytopt:46] 

Loading ytopt
--------------
2023-06-29 16:09:53|29625|ERROR|ytopt:49] Uncaught exception:
Traceback (most recent call last):
  File "/Users/praveen_paramasivam/anaconda3/envs/ytuneV1/lib/python3.10/runpy.py", line 196, in _run_module_as_main
    return _run_code(code, main_globals, None,
  File "/Users/praveen_paramasivam/anaconda3/envs/ytuneV1/lib/python3.10/runpy.py", line 86, in _run_code
    exec(code, run_globals)
  File "/Users/praveen_paramasivam/workspace/anl/ytoptWorkspaceNew/ytuneV1/ytopt/ytopt/search/ambs.py", line 125, in <module>
    search = AMBS(**vars(args))
  File "/Users/praveen_paramasivam/workspace/anl/ytoptWorkspaceNew/ytuneV1/ytopt/ytopt/search/ambs.py", line 45, in __init__
    super().__init__(**kwargs)
  File "/Users/praveen_paramasivam/workspace/anl/ytoptWorkspaceNew/ytuneV1/ytopt/ytopt/search/search.py", line 38, in __init__
    self.problem = util.generic_loader(problem, 'Problem')
  File "/Users/praveen_paramasivam/workspace/anl/ytoptWorkspaceNew/ytuneV1/ytopt/ytopt/search/util.py", line 125, in generic_loader
    return load_attr_from(target)
  File "/Users/praveen_paramasivam/workspace/anl/ytoptWorkspaceNew/ytuneV1/ytopt/ytopt/search/util.py", line 100, in load_attr_from
    module = import_module(str_module)
  File "/Users/praveen_paramasivam/anaconda3/envs/ytuneV1/lib/python3.10/importlib/__init__.py", line 126, in import_module
    return _bootstrap._gcd_import(name[level:], package, level)
  File "<frozen importlib._bootstrap>", line 1050, in _gcd_import
  File "<frozen importlib._bootstrap>", line 1027, in _find_and_load
  File "<frozen importlib._bootstrap>", line 1006, in _find_and_load_unlocked
  File "<frozen importlib._bootstrap>", line 688, in _load_unlocked
  File "<frozen importlib._bootstrap_external>", line 883, in exec_module
  File "<frozen importlib._bootstrap>", line 241, in _call_with_frames_removed
  File "/Users/praveen_paramasivam/workspace/anl/ytoptWorkspaceNew/ytuneV1/ytopt-libensemble/ytopt-libe-deeplearning/pytorch/ytopt/problem.py", line 63, in <module>
    Problem = TuningProblem(
TypeError: TuningProblem.__init__() missing 1 required positional argument: 'parameter_space'
2023-06-29 16:10:51|29705|INFO|ytopt:46] 

Loading ytopt
--------------
2023-06-29 16:10:51|29705|ERROR|ytopt:49] Uncaught exception:
Traceback (most recent call last):
  File "/Users/praveen_paramasivam/anaconda3/envs/ytuneV1/lib/python3.10/runpy.py", line 196, in _run_module_as_main
    return _run_code(code, main_globals, None,
  File "/Users/praveen_paramasivam/anaconda3/envs/ytuneV1/lib/python3.10/runpy.py", line 86, in _run_code
    exec(code, run_globals)
  File "/Users/praveen_paramasivam/workspace/anl/ytoptWorkspaceNew/ytuneV1/ytopt/ytopt/search/ambs.py", line 125, in <module>
    search = AMBS(**vars(args))
  File "/Users/praveen_paramasivam/workspace/anl/ytoptWorkspaceNew/ytuneV1/ytopt/ytopt/search/ambs.py", line 45, in __init__
    super().__init__(**kwargs)
  File "/Users/praveen_paramasivam/workspace/anl/ytoptWorkspaceNew/ytuneV1/ytopt/ytopt/search/search.py", line 38, in __init__
    self.problem = util.generic_loader(problem, 'Problem')
  File "/Users/praveen_paramasivam/workspace/anl/ytoptWorkspaceNew/ytuneV1/ytopt/ytopt/search/util.py", line 125, in generic_loader
    return load_attr_from(target)
  File "/Users/praveen_paramasivam/workspace/anl/ytoptWorkspaceNew/ytuneV1/ytopt/ytopt/search/util.py", line 100, in load_attr_from
    module = import_module(str_module)
  File "/Users/praveen_paramasivam/anaconda3/envs/ytuneV1/lib/python3.10/importlib/__init__.py", line 126, in import_module
    return _bootstrap._gcd_import(name[level:], package, level)
  File "<frozen importlib._bootstrap>", line 1050, in _gcd_import
  File "<frozen importlib._bootstrap>", line 1027, in _find_and_load
  File "<frozen importlib._bootstrap>", line 1006, in _find_and_load_unlocked
  File "<frozen importlib._bootstrap>", line 688, in _load_unlocked
  File "<frozen importlib._bootstrap_external>", line 883, in exec_module
  File "<frozen importlib._bootstrap>", line 241, in _call_with_frames_removed
  File "/Users/praveen_paramasivam/workspace/anl/ytoptWorkspaceNew/ytuneV1/ytopt-libensemble/ytopt-libe-deeplearning/pytorch/ytopt/problem.py", line 63, in <module>
    Problem = TuningProblem(
TypeError: TuningProblem.__init__() missing 1 required positional argument: 'parameter_space'
2023-06-29 16:11:41|29854|INFO|ytopt:46] 

Loading ytopt
--------------
2023-06-29 16:11:41|29854|ERROR|ytopt:49] Uncaught exception:
Traceback (most recent call last):
  File "/Users/praveen_paramasivam/anaconda3/envs/ytuneV1/lib/python3.10/runpy.py", line 196, in _run_module_as_main
    return _run_code(code, main_globals, None,
  File "/Users/praveen_paramasivam/anaconda3/envs/ytuneV1/lib/python3.10/runpy.py", line 86, in _run_code
    exec(code, run_globals)
  File "/Users/praveen_paramasivam/workspace/anl/ytoptWorkspaceNew/ytuneV1/ytopt/ytopt/search/ambs.py", line 125, in <module>
    search = AMBS(**vars(args))
  File "/Users/praveen_paramasivam/workspace/anl/ytoptWorkspaceNew/ytuneV1/ytopt/ytopt/search/ambs.py", line 45, in __init__
    super().__init__(**kwargs)
  File "/Users/praveen_paramasivam/workspace/anl/ytoptWorkspaceNew/ytuneV1/ytopt/ytopt/search/search.py", line 38, in __init__
    self.problem = util.generic_loader(problem, 'Problem')
  File "/Users/praveen_paramasivam/workspace/anl/ytoptWorkspaceNew/ytuneV1/ytopt/ytopt/search/util.py", line 125, in generic_loader
    return load_attr_from(target)
  File "/Users/praveen_paramasivam/workspace/anl/ytoptWorkspaceNew/ytuneV1/ytopt/ytopt/search/util.py", line 100, in load_attr_from
    module = import_module(str_module)
  File "/Users/praveen_paramasivam/anaconda3/envs/ytuneV1/lib/python3.10/importlib/__init__.py", line 126, in import_module
    return _bootstrap._gcd_import(name[level:], package, level)
  File "<frozen importlib._bootstrap>", line 1050, in _gcd_import
  File "<frozen importlib._bootstrap>", line 1027, in _find_and_load
  File "<frozen importlib._bootstrap>", line 1006, in _find_and_load_unlocked
  File "<frozen importlib._bootstrap>", line 688, in _load_unlocked
  File "<frozen importlib._bootstrap_external>", line 883, in exec_module
  File "<frozen importlib._bootstrap>", line 241, in _call_with_frames_removed
  File "/Users/praveen_paramasivam/workspace/anl/ytoptWorkspaceNew/ytuneV1/ytopt-libensemble/ytopt-libe-deeplearning/pytorch/ytopt/problem.py", line 63, in <module>
    Problem = TuningProblem(
TypeError: TuningProblem.__init__() missing 1 required positional argument: 'parameter_space'
2023-06-30 19:45:20|79114|INFO|ytopt:46] 

Loading ytopt
--------------
2023-06-30 19:45:20|79114|ERROR|ytopt:49] Uncaught exception:
Traceback (most recent call last):
  File "/Users/praveen_paramasivam/anaconda3/envs/ytuneV1/lib/python3.10/runpy.py", line 196, in _run_module_as_main
    return _run_code(code, main_globals, None,
  File "/Users/praveen_paramasivam/anaconda3/envs/ytuneV1/lib/python3.10/runpy.py", line 86, in _run_code
    exec(code, run_globals)
  File "/Users/praveen_paramasivam/workspace/anl/ytoptWorkspaceNew/ytuneV1/ytopt/ytopt/search/ambs.py", line 125, in <module>
    search = AMBS(**vars(args))
  File "/Users/praveen_paramasivam/workspace/anl/ytoptWorkspaceNew/ytuneV1/ytopt/ytopt/search/ambs.py", line 45, in __init__
    super().__init__(**kwargs)
  File "/Users/praveen_paramasivam/workspace/anl/ytoptWorkspaceNew/ytuneV1/ytopt/ytopt/search/search.py", line 38, in __init__
    self.problem = util.generic_loader(problem, 'Problem')
  File "/Users/praveen_paramasivam/workspace/anl/ytoptWorkspaceNew/ytuneV1/ytopt/ytopt/search/util.py", line 125, in generic_loader
    return load_attr_from(target)
  File "/Users/praveen_paramasivam/workspace/anl/ytoptWorkspaceNew/ytuneV1/ytopt/ytopt/search/util.py", line 100, in load_attr_from
    module = import_module(str_module)
  File "/Users/praveen_paramasivam/anaconda3/envs/ytuneV1/lib/python3.10/importlib/__init__.py", line 126, in import_module
    return _bootstrap._gcd_import(name[level:], package, level)
  File "<frozen importlib._bootstrap>", line 1050, in _gcd_import
  File "<frozen importlib._bootstrap>", line 1027, in _find_and_load
  File "<frozen importlib._bootstrap>", line 1006, in _find_and_load_unlocked
  File "<frozen importlib._bootstrap>", line 688, in _load_unlocked
  File "<frozen importlib._bootstrap_external>", line 883, in exec_module
  File "<frozen importlib._bootstrap>", line 241, in _call_with_frames_removed
  File "/Users/praveen_paramasivam/workspace/anl/ytoptWorkspaceNew/ytuneV1/ytopt-libensemble/ytopt-libe-deeplearning/pytorch/ytopt/problem.py", line 63, in <module>
    Problem = TuningProblem(
TypeError: TuningProblem.__init__() missing 1 required positional argument: 'parameter_space'
2023-06-30 19:49:14|79577|INFO|ytopt:46] 

Loading ytopt
--------------
2023-06-30 19:49:14|79577|ERROR|ytopt:49] Uncaught exception:
Traceback (most recent call last):
  File "/Users/praveen_paramasivam/anaconda3/envs/ytuneV1/lib/python3.10/runpy.py", line 196, in _run_module_as_main
    return _run_code(code, main_globals, None,
  File "/Users/praveen_paramasivam/anaconda3/envs/ytuneV1/lib/python3.10/runpy.py", line 86, in _run_code
    exec(code, run_globals)
  File "/Users/praveen_paramasivam/workspace/anl/ytoptWorkspaceNew/ytuneV1/ytopt/ytopt/search/ambs.py", line 125, in <module>
    search = AMBS(**vars(args))
  File "/Users/praveen_paramasivam/workspace/anl/ytoptWorkspaceNew/ytuneV1/ytopt/ytopt/search/ambs.py", line 45, in __init__
    super().__init__(**kwargs)
  File "/Users/praveen_paramasivam/workspace/anl/ytoptWorkspaceNew/ytuneV1/ytopt/ytopt/search/search.py", line 38, in __init__
    self.problem = util.generic_loader(problem, 'Problem')
  File "/Users/praveen_paramasivam/workspace/anl/ytoptWorkspaceNew/ytuneV1/ytopt/ytopt/search/util.py", line 125, in generic_loader
    return load_attr_from(target)
  File "/Users/praveen_paramasivam/workspace/anl/ytoptWorkspaceNew/ytuneV1/ytopt/ytopt/search/util.py", line 100, in load_attr_from
    module = import_module(str_module)
  File "/Users/praveen_paramasivam/anaconda3/envs/ytuneV1/lib/python3.10/importlib/__init__.py", line 126, in import_module
    return _bootstrap._gcd_import(name[level:], package, level)
  File "<frozen importlib._bootstrap>", line 1050, in _gcd_import
  File "<frozen importlib._bootstrap>", line 1027, in _find_and_load
  File "<frozen importlib._bootstrap>", line 1006, in _find_and_load_unlocked
  File "<frozen importlib._bootstrap>", line 688, in _load_unlocked
  File "<frozen importlib._bootstrap_external>", line 883, in exec_module
  File "<frozen importlib._bootstrap>", line 241, in _call_with_frames_removed
  File "/Users/praveen_paramasivam/workspace/anl/ytoptWorkspaceNew/ytuneV1/ytopt-libensemble/ytopt-libe-deeplearning/pytorch/ytopt/problem.py", line 63, in <module>
    Problem = TuningProblem(
TypeError: TuningProblem.__init__() missing 1 required positional argument: 'parameter_space'
